Workbook
Name KategorienListe: Kategorien!$A$3:$A$9

Sheet Anleitung1
B2: GSH Schuljahreskalender - Anleitung
B4: Was ist das?
B5: dem Konverter-Tool zu einer ICS-Datei und importierst sie in IServ.
B6: Gesamter Ablauf (einmal pro Schuljahr)
B7: 1. | C7: Ferien eintragen - Tab "Ferien" oeffnen und Ferientermine fuer das neue Schuljahr eintragen.
B8: 2. | C8: Termine eintragen - Tab "Terminplan" oeffnen und alle Schultermine eintragen.
B9: 3. | C9: Konverter oeffnen - Datei GSH_Terminplan_Konverter.html im Browser oeffnen (Chrome empfohlen).
B10: 4. | C10: Excel importieren - Diese Excel-Datei in das Konverter-Tool ziehen.
B11: 5. | C11: ICS herunterladen - Auf "ICS herunterladen" klicken. Datei wird im Download-Ordner gespeichert.
B12: 6. | C12: ICS in IServ importieren - In IServ -> Kalender -> Einstellungen -> Importieren -> ICS-Datei auswaehlen.
B14: So traegst du Termine ein (Tab "Terminplan")
B15: 1. | C15: Schulwoche finden - Spalte D zeigt die Woche (z.B. "25.08. - 29.08.2025"). Richtige Woche suchen.
B16: 2. | C16: Wochentag waehlen - In Spalte E klicken - Dropdown erscheint (Mo / Di / Mi / Do / Fr / Ganze Woche).
B17: 3. | C17: Uhrzeit eintragen - Start- und Endzeit in Spalte F/G eintragen (Format: 08:30). Leer = ganztaegig.
B18: 4. | C18: Titel eintragen - Bezeichnung des Termins in Spalte H eintragen (Pflichtfeld).
B19: 5. | C19: Kategorie waehlen - In Spalte I klicken - Dropdown mit allen Kategorien erscheint.
B20: 6. | C20: Ganztaegig setzen - In Spalte J "Ja" waehlen, wenn der Termin den ganzen Tag dauert.
B22: Spalten des Terminplans
B23: Spalte | C23: Bedeutung und Beispiel
B24: D Schulwoche | C24: Wird automatisch berechnet - NICHT bearbeiten! (z.B. "25.08. - 29.08.2025")
B25: E Wochentag | C25: Dropdown: Mo / Di / Mi / Do / Fr / Ganze Woche
B26: F Uhrzeit | C26: Startzeit (Format: 09:30). Leer lassen wenn ganztaegig.
B27: G Endzeit | C27: Endzeit (Format: 11:00). Optional.
B28: H Titel | C28: Bezeichnung des Termins - Pflichtfeld! (z.B. "Lehrerkonferenz")
B29: I Kategorie | C29: Dropdown: eine der 7 Kategorien auswaehlen
B30: J Ganztaegig | C30: Dropdown: "Ja" wenn kein fester Zeitraum
B31: K Anmerkung | C31: Optionaler Hinweistext (z.B. "Bitte alle Lehrkraefte")
B33: Wichtige Hinweise
B34: >> Graue Header-Zeilen markieren den Wochenbeginn - dort NICHTS eintragen!
B35: >> Spalten A, B, C sind ausgeblendet (technische Daten) - nicht einblenden.
B36: >> Spalte D wird automatisch berechnet - nicht bearbeiten.
B37: >> Ferientermine zuerst im Tab "Ferien" eintragen - danach passen sich alle Daten an.
B38: >> Aenderungen im laufenden Schuljahr: direkt im IServ-Kalender bearbeiten.
B40: Verfuegbare Kategorien
B41: Jahrgang 5/6 | C41: Einschulung, Sprachstandstest, Neue 5er
B42: Jahrgang 7/8 | C42: Potenzialanalyse, WP-Wahl, KAoA
B43: Jahrgang 9/10 | C43: Betriebspraktikum, ZP 10, Abschlussfahrt
B44: Oberstufe | C44: Abitur, EF/Q1/Q2 Termine
B45: Inklusion | C45: IFOe, AL SuS, Inklusionsteam
B46: Feiertage/Ferien | C46: Ferien, Feiertage, schulfreie Tage
...

Sheet Anleitung
B2: GSH Schuljahreskalender - Anleitung
B4: Was ist das?
B5: dem Konverter-Tool zu einer ICS-Datei und importierst sie in IServ.
B6: Gesamter Ablauf (einmal pro Schuljahr)
B7: 1. | C7: Ferien eintragen - Tab "Ferien" oeffnen und Ferientermine fuer das neue Schuljahr eintragen.
B8: 2. | C8: Termine eintragen - Tab "Terminplan" oeffnen und alle Schultermine eintragen.
B9: 3. | C9: Konverter oeffnen - Datei GSH_Terminplan_Konverter.html im Browser oeffnen (Chrome empfohlen).
B10: 4. | C10: Excel importieren - Diese Excel-Datei in das Konverter-Tool ziehen.
B11: 5. | C11: ICS herunterladen - Auf "ICS herunterladen" klicken. Datei wird im Download-Ordner gespeichert.
B12: 6. | C12: ICS in IServ importieren - In IServ -> Kalender -> Einstellungen -> Importieren -> ICS-Datei auswaehlen.
B14: So traegst du Termine ein (Tab "Terminplan")
B15: 1. | C15: Schulwoche finden - Spalte D zeigt die Woche (z.B. "25.08. - 29.08.2025"). Richtige Woche suchen.
B16: 2. | C16: Wochentag waehlen - In Spalte E klicken - Dropdown erscheint (Mo / Di / Mi / Do / Fr / Ganze Woche).
B17: 3. | C17: Uhrzeit eintragen - Start- und Endzeit in Spalte F/G eintragen (Format: 08:30). Leer = ganztaegig.
B18: 4. | C18: Titel eintragen - Bezeichnung des Termins in Spalte H eintragen (Pflichtfeld).
B19: 5. | C19: Kategorie waehlen - In Spalte I klicken - Dropdown mit allen Kategorien erscheint.
B20: 6. | C20: Ganztaegig setzen - In Spalte J "Ja" waehlen, wenn der Termin den ganzen Tag dauert.
B22: Spalten des Terminplans
B23: Spalte | C23: Bedeutung und Beispiel
B24: D Schulwoche | C24: Wird automatisch berechnet - NICHT bearbeiten! (z.B. "25.08. - 29.08.2025")
B25: E Wochentag | C25: Dropdown: Mo / Di / Mi / Do / Fr / Ganze Woche
B26: F Uhrzeit | C26: Startzeit (Format: 09:30). Leer lassen wenn ganztaegig.
B27: G Endzeit | C27: Endzeit (Format: 11:00). Optional.
B28: H Titel | C28: Bezeichnung des Termins - Pflichtfeld! (z.B. "Lehrerkonferenz")
B29: I Kategorie | C29: Dropdown: eine der 7 Kategorien auswaehlen
B30: J Ganztaegig | C30: Dropdown: "Ja" wenn kein fester Zeitraum
B31: K Anmerkung | C31: Optionaler Hinweistext (z.B. "Bitte alle Lehrkraefte")
B33: Wichtige Hinweise
B34: >> Graue Header-Zeilen markieren den Wochenbeginn - dort NICHTS eintragen!
B35: >> Spalten A, B, C sind ausgeblendet (technische Daten) - nicht einblenden.
B36: >> Spalte D wird automatisch berechnet - nicht bearbeiten.
B37: >> Ferientermine zuerst im Tab "Ferien" eintragen - danach passen sich alle Daten an.
B38: >> Aenderungen im laufenden Schuljahr: direkt im IServ-Kalender bearbeiten.
B40: Verfuegbare Kategorien
B41: Jahrgang 5/6 | C41: Einschulung, Sprachstandstest, Neue 5er
B42: Jahrgang 7/8 | C42: Potenzialanalyse, WP-Wahl, KAoA
B43: Jahrgang 9/10 | C43: Betriebspraktikum, ZP 10, Abschlussfahrt
B44: Oberstufe | C44: Abitur, EF/Q1/Q2 Termine
B45: Inklusion | C45: IFOe, AL SuS, Inklusionsteam
B46: Feiertage/Ferien | C46: Ferien, Feiertage, schulfreie Tage
...

Sheet Terminplan
A1: SW-Key | B1: Montag-ISO | C1: SW | D1: Schulwoche | E1: Wochentag | F1: Uhrzeit | G1: Endzeit | H1: Titel / Veranstaltung | I1: Kategorie | J1: Ganztaegig | K1: Anmerkung
A2: SW 00 | B2: =Ferien!$F$15 | C2: SW 00 | D2: =TEXT(B2,"TT.MM.")&" – "&TEXT(B2+4,"TT.MM.JJJJ")
A11: SW 01 | B11: =Ferien!$F$16 | C11: SW 01 | D11: =TEXT(B11,"TT.MM.")&" – "&TEXT(B11+4,"TT.MM.JJJJ")
A20: SW 02 | B20: =Ferien!$F$17 | C20: SW 02 | D20: =TEXT(B20,"TT.MM.")&" – "&TEXT(B20+4,"TT.MM.JJJJ")
A29: SW 03 | B29: =Ferien!$F$18 | C29: SW 03 | D29: =TEXT(B29,"TT.MM.")&" – "&TEXT(B29+4,"TT.MM.JJJJ")
A38: SW 04 | B38: =Ferien!$F$19 | C38: SW 04 | D38: =TEXT(B38,"TT.MM.")&" – "&TEXT(B38+4,"TT.MM.JJJJ")
A47: SW 05 | B47: =Ferien!$F$20 | C47: SW 05 | D47: =TEXT(B47,"TT.MM.")&" – "&TEXT(B47+4,"TT.MM.JJJJ")
A56: SW 06 | B56: =Ferien!$F$21 | C56: SW 06 | D56: =TEXT(B56,"TT.MM.")&" – "&TEXT(B56+4,"TT.MM.JJJJ")
A65: SW 07 | B65: =Ferien!$F$22 | C65: SW 07 | D65: =TEXT(B65,"TT.MM.")&" – "&TEXT(B65+4,"TT.MM.JJJJ")
A74: FERIEN | B74: 2025-10-13 | C74: FERIEN | D74: 13.10.2025 – 24.10.2025 | H74: Herbstferien | I74: Feiertage/Ferien
A75: SW 08 | B75: =Ferien!$F$23 | C75: SW 08 | D75: =TEXT(B75,"TT.MM.")&" – "&TEXT(B75+4,"TT.MM.JJJJ")
A84: SW 09 | B84: =Ferien!$F$24 | C84: SW 09 | D84: =TEXT(B84,"TT.MM.")&" – "&TEXT(B84+4,"TT.MM.JJJJ")
A93: SW 10 | B93: =Ferien!$F$25 | C93: SW 10 | D93: =TEXT(B93,"TT.MM.")&" – "&TEXT(B93+4,"TT.MM.JJJJ")
A102: SW 11 | B102: =Ferien!$F$26 | C102: SW 11 | D102: =TEXT(B102,"TT.MM.")&" – "&TEXT(B102+4,"TT.MM.JJJJ")
A111: SW 12 | B111: =Ferien!$F$27 | C111: SW 12 | D111: =TEXT(B111,"TT.MM.")&" – "&TEXT(B111+4,"TT.MM.JJJJ")
A120: SW 13 | B120: =Ferien!$F$28 | C120: SW 13 | D120: =TEXT(B120,"TT.MM.")&" – "&TEXT(B120+4,"TT.MM.JJJJ")
A129: SW 14 | B129: =Ferien!$F$29 | C129: SW 14 | D129: =TEXT(B129,"TT.MM.")&" – "&TEXT(B129+4,"TT.MM.JJJJ")
A138: SW 15 | B138: =Ferien!$F$30 | C138: SW 15 | D138: =TEXT(B138,"TT.MM.")&" – "&TEXT(B138+4,"TT.MM.JJJJ")
A147: FERIEN | B147: 2025-12-22 | C147: FERIEN | D147: 22.12.2025 – 02.01.2026 | H147: Weihnachtsferien | I147: Feiertage/Ferien
A148: SW 16 | B148: =Ferien!$F$31 | C148: SW 16 | D148: =TEXT(B148,"TT.MM.")&" – "&TEXT(B148+4,"TT.MM.JJJJ")
A157: SW 17 | B157: =Ferien!$F$32 | C157: SW 17 | D157: =TEXT(B157,"TT.MM.")&" – "&TEXT(B157+4,"TT.MM.JJJJ")
A166: SW 18 | B166: =Ferien!$F$33 | C166: SW 18 | D166: =TEXT(B166,"TT.MM.")&" – "&TEXT(B166+4,"TT.MM.JJJJ")
A175: SW 19 | B175: =Ferien!$F$34 | C175: SW 19 | D175: =TEXT(B175,"TT.MM.")&" – "&TEXT(B175+4,"TT.MM.JJJJ")
A184: SW 20 | B184: =Ferien!$F$35 | C184: SW 20 | D184: =TEXT(B184,"TT.MM.")&" – "&TEXT(B184+4,"TT.MM.JJJJ")
A193: SW 21 | B193: =Ferien!$F$36 | C193: SW 21 | D193: =TEXT(B193,"TT.MM.")&" – "&TEXT(B193+4,"TT.MM.JJJJ")
A202: SW 22 | B202: =Ferien!$F$37 | C202: SW 22 | D202: =TEXT(B202,"TT.MM.")&" – "&TEXT(B202+4,"TT.MM.JJJJ")
A211: SW 23 | B211: =Ferien!$F$38 | C211: SW 23 | D211: =TEXT(B211,"TT.MM.")&" – "&TEXT(B211+4,"TT.MM.JJJJ")
A220: SW 24 | B220: =Ferien!$F$39 | C220: SW 24 | D220: =TEXT(B220,"TT.MM.")&" – "&TEXT(B220+4,"TT.MM.JJJJ")
A229: SW 25 | B229: =Ferien!$F$40 | C229: SW 25 | D229: =TEXT(B229,"TT.MM.")&" – "&TEXT(B229+4,"TT.MM.JJJJ")
A238: SW 26 | B238: =Ferien!$F$41 | C238: SW 26 | D238: =TEXT(B238,"TT.MM.")&" – "&TEXT(B238+4,"TT.MM.JJJJ")
A247: SW 27 | B247: =Ferien!$F$42 | C247: SW 27 | D247: =TEXT(B247,"TT.MM.")&" – "&TEXT(B247+4,"TT.MM.JJJJ")
A256: FERIEN | B256: 2026-03-30 | C256: FERIEN | D256: 30.03.2026 – 10.04.2026 | H256: Osterferien | I256: Feiertage/Ferien
A257: SW 28 | B257: =Ferien!$F$43 | C257: SW 28 | D257: =TEXT(B257,"TT.MM.")&" – "&TEXT(B257+4,"TT.MM.JJJJ")
A266: SW 29 | B266: =Ferien!$F$44 | C266: SW 29 | D266: =TEXT(B266,"TT.MM.")&" – "&TEXT(B266+4,"TT.MM.JJJJ")
A275: SW 30 | B275: =Ferien!$F$45 | C275: SW 30 | D275: =TEXT(B275,"TT.MM.")&" – "&TEXT(B275+4,"TT.MM.JJJJ")
A284: SW 31 | B284: =Ferien!$F$46 | C284: SW 31 | D284: =TEXT(B284,"TT.MM.")&" – "&TEXT(B284+4,"TT.MM.JJJJ")
A293: SW 32 | B293: =Ferien!$F$47 | C293: SW 32 | D293: =TEXT(B293,"TT.MM.")&" – "&TEXT(B293+4,"TT.MM.JJJJ")
A302: SW 33 | B302: =Ferien!$F$48 | C302: SW 33 | D302: =TEXT(B302,"TT.MM.")&" – "&TEXT(B302+4,"TT.MM.JJJJ")
A311: FERIEN | B311: 2026-05-25 | C311: FERIEN | D311: 25.05.2026 – 29.05.2026 | H311: Pfingstferien | I311: Feiertage/Ferien
A312: SW 34 | B312: =Ferien!$F$49 | C312: SW 34 | D312: =TEXT(B312,"TT.MM.")&" – "&TEXT(B312+4,"TT.MM.JJJJ")
...

Sheet Ferien
A1: =IFERROR("Schuljahr "&TEXT(YEAR($B$10),"0")&"/"&TEXT(YEAR($B$10)+1-2000,"00")&" – Ferienliste","Ferienliste")
A2: Bezeichnung | B2: Von (Datum) | C2: Bis (Datum) | D2: Anmerkung
A3: Herbstferien | B3: 45943 | C3: 45954
A4: Weihnachtsferien | B4: 46013 | C4: 46024
A5: Osterferien | B5: 46111 | C5: 46122
A6: Pfingstferien | B6: 46167 | C6: 46171
A7: Sommerferien | B7: 46223 | C7: 46266
A9: Schuljahres-Eckdaten (automatisch berechnet - nicht aendern)
A10: Erster Schultag (SW 00) | B10: 45887
A11: Erster Unterrichtstag | B11: 45894
A12: Letzter Schultag (SW 40) | B12: 46220
E14: Berechnete Schulmontage – NICHT manuell ändern
E15: SW 00 | F15: =$B$10
E16: SW 01 | F16: =$F$15+7+IF(ISBLANK($B$3),0,IF(($F$15+7>=$B$3)*($F$15+7<=$C$3),$C$3+8-WEEKDAY($C$3,2)-($F$15+7),0))+IF(ISBLANK($B$4),0,IF(($F$15+7>=$B$4)*($F$15+7<=$C$4),$C$4+8-WEEKDAY($C$4,2)-($F$15+7),0))+IF(ISBLANK($B$5),0,IF(($F$15+7>=$B$5)*($F$15+7<=$C$5),$C$5+8-WEEKDAY($C$5,2)-($F$15+7),0))+IF(ISBLANK($B$6),0,IF(($F$15+7>=$B$6)*($F$15+7<=$C$6),$C$6+8-WEEKDAY($C$6,2)-($F$15+7),0))
E17: SW 02 | F17: =$F$16+7+IF(ISBLANK($B$3),0,IF(($F$16+7>=$B$3)*($F$16+7<=$C$3),$C$3+8-WEEKDAY($C$3,2)-($F$16+7),0))+IF(ISBLANK($B$4),0,IF(($F$16+7>=$B$4)*($F$16+7<=$C$4),$C$4+8-WEEKDAY($C$4,2)-($F$16+7),0))+IF(ISBLANK($B$5),0,IF(($F$16+7>=$B$5)*($F$16+7<=$C$5),$C$5+8-WEEKDAY($C$5,2)-($F$16+7),0))+IF(ISBLANK($B$6),0,IF(($F$16+7>=$B$6)*($F$16+7<=$C$6),$C$6+8-WEEKDAY($C$6,2)-($F$16+7),0))
E18: SW 03 | F18: =$F$17+7+IF(ISBLANK($B$3),0,IF(($F$17+7>=$B$3)*($F$17+7<=$C$3),$C$3+8-WEEKDAY($C$3,2)-($F$17+7),0))+IF(ISBLANK($B$4),0,IF(($F$17+7>=$B$4)*($F$17+7<=$C$4),$C$4+8-WEEKDAY($C$4,2)-($F$17+7),0))+IF(ISBLANK($B$5),0,IF(($F$17+7>=$B$5)*($F$17+7<=$C$5),$C$5+8-WEEKDAY($C$5,2)-($F$17+7),0))+IF(ISBLANK($B$6),0,IF(($F$17+7>=$B$6)*($F$17+7<=$C$6),$C$6+8-WEEKDAY($C$6,2)-($F$17+7),0))
E19: SW 04 | F19: =$F$18+7+IF(ISBLANK($B$3),0,IF(($F$18+7>=$B$3)*($F$18+7<=$C$3),$C$3+8-WEEKDAY($C$3,2)-($F$18+7),0))+IF(ISBLANK($B$4),0,IF(($F$18+7>=$B$4)*($F$18+7<=$C$4),$C$4+8-WEEKDAY($C$4,2)-($F$18+7),0))+IF(ISBLANK($B$5),0,IF(($F$18+7>=$B$5)*($F$18+7<=$C$5),$C$5+8-WEEKDAY($C$5,2)-($F$18+7),0))+IF(ISBLANK($B$6),0,IF(($F$18+7>=$B$6)*($F$18+7<=$C$6),$C$6+8-WEEKDAY($C$6,2)-($F$18+7),0))
E20: SW 05 | F20: =$F$19+7+IF(ISBLANK($B$3),0,IF(($F$19+7>=$B$3)*($F$19+7<=$C$3),$C$3+8-WEEKDAY($C$3,2)-($F$19+7),0))+IF(ISBLANK($B$4),0,IF(($F$19+7>=$B$4)*($F$19+7<=$C$4),$C$4+8-WEEKDAY($C$4,2)-($F$19+7),0))+IF(ISBLANK($B$5),0,IF(($F$19+7>=$B$5)*($F$19+7<=$C$5),$C$5+8-WEEKDAY($C$5,2)-($F$19+7),0))+IF(ISBLANK($B$6),0,IF(($F$19+7>=$B$6)*($F$19+7<=$C$6),$C$6+8-WEEKDAY($C$6,2)-($F$19+7),0))
E21: SW 06 | F21: =$F$20+7+IF(ISBLANK($B$3),0,IF(($F$20+7>=$B$3)*($F$20+7<=$C$3),$C$3+8-WEEKDAY($C$3,2)-($F$20+7),0))+IF(ISBLANK($B$4),0,IF(($F$20+7>=$B$4)*($F$20+7<=$C$4),$C$4+8-WEEKDAY($C$4,2)-($F$20+7),0))+IF(ISBLANK($B$5),0,IF(($F$20+7>=$B$5)*($F$20+7<=$C$5),$C$5+8-WEEKDAY($C$5,2)-($F$20+7),0))+IF(ISBLANK($B$6),0,IF(($F$20+7>=$B$6)*($F$20+7<=$C$6),$C$6+8-WEEKDAY($C$6,2)-($F$20+7),0))
E22: SW 07 | F22: =$F$21+7+IF(ISBLANK($B$3),0,IF(($F$21+7>=$B$3)*($F$21+7<=$C$3),$C$3+8-WEEKDAY($C$3,2)-($F$21+7),0))+IF(ISBLANK($B$4),0,IF(($F$21+7>=$B$4)*($F$21+7<=$C$4),$C$4+8-WEEKDAY($C$4,2)-($F$21+7),0))+IF(ISBLANK($B$5),0,IF(($F$21+7>=$B$5)*($F$21+7<=$C$5),$C$5+8-WEEKDAY($C$5,2)-($F$21+7),0))+IF(ISBLANK($B$6),0,IF(($F$21+7>=$B$6)*($F$21+7<=$C$6),$C$6+8-WEEKDAY($C$6,2)-($F$21+7),0))
E23: SW 08 | F23: =$F$22+7+IF(ISBLANK($B$3),0,IF(($F$22+7>=$B$3)*($F$22+7<=$C$3),$C$3+8-WEEKDAY($C$3,2)-($F$22+7),0))+IF(ISBLANK($B$4),0,IF(($F$22+7>=$B$4)*($F$22+7<=$C$4),$C$4+8-WEEKDAY($C$4,2)-($F$22+7),0))+IF(ISBLANK($B$5),0,IF(($F$22+7>=$B$5)*($F$22+7<=$C$5),$C$5+8-WEEKDAY($C$5,2)-($F$22+7),0))+IF(ISBLANK($B$6),0,IF(($F$22+7>=$B$6)*($F$22+7<=$C$6),$C$6+8-WEEKDAY($C$6,2)-($F$22+7),0))
E24: SW 09 | F24: =$F$23+7+IF(ISBLANK($B$3),0,IF(($F$23+7>=$B$3)*($F$23+7<=$C$3),$C$3+8-WEEKDAY($C$3,2)-($F$23+7),0))+IF(ISBLANK($B$4),0,IF(($F$23+7>=$B$4)*($F$23+7<=$C$4),$C$4+8-WEEKDAY($C$4,2)-($F$23+7),0))+IF(ISBLANK($B$5),0,IF(($F$23+7>=$B$5)*($F$23+7<=$C$5),$C$5+8-WEEKDAY($C$5,2)-($F$23+7),0))+IF(ISBLANK($B$6),0,IF(($F$23+7>=$B$6)*($F$23+7<=$C$6),$C$6+8-WEEKDAY($C$6,2)-($F$23+7),0))
E25: SW 10 | F25: =$F$24+7+IF(ISBLANK($B$3),0,IF(($F$24+7>=$B$3)*($F$24+7<=$C$3),$C$3+8-WEEKDAY($C$3,2)-($F$24+7),0))+IF(ISBLANK($B$4),0,IF(($F$24+7>=$B$4)*($F$24+7<=$C$4),$C$4+8-WEEKDAY($C$4,2)-($F$24+7),0))+IF(ISBLANK($B$5),0,IF(($F$24+7>=$B$5)*($F$24+7<=$C$5),$C$5+8-WEEKDAY($C$5,2)-($F$24+7),0))+IF(ISBLANK($B$6),0,IF(($F$24+7>=$B$6)*($F$24+7<=$C$6),$C$6+8-WEEKDAY($C$6,2)-($F$24+7),0))
E26: SW 11 | F26: =$F$25+7+IF(ISBLANK($B$3),0,IF(($F$25+7>=$B$3)*($F$25+7<=$C$3),$C$3+8-WEEKDAY($C$3,2)-($F$25+7),0))+IF(ISBLANK($B$4),0,IF(($F$25+7>=$B$4)*($F$25+7<=$C$4),$C$4+8-WEEKDAY($C$4,2)-($F$25+7),0))+IF(ISBLANK($B$5),0,IF(($F$25+7>=$B$5)*($F$25+7<=$C$5),$C$5+8-WEEKDAY($C$5,2)-($F$25+7),0))+IF(ISBLANK($B$6),0,IF(($F$25+7>=$B$6)*($F$25+7<=$C$6),$C$6+8-WEEKDAY($C$6,2)-($F$25+7),0))
E27: SW 12 | F27: =$F$26+7+IF(ISBLANK($B$3),0,IF(($F$26+7>=$B$3)*($F$26+7<=$C$3),$C$3+8-WEEKDAY($C$3,2)-($F$26+7),0))+IF(ISBLANK($B$4),0,IF(($F$26+7>=$B$4)*($F$26+7<=$C$4),$C$4+8-WEEKDAY($C$4,2)-($F$26+7),0))+IF(ISBLANK($B$5),0,IF(($F$26+7>=$B$5)*($F$26+7<=$C$5),$C$5+8-WEEKDAY($C$5,2)-($F$26+7),0))+IF(ISBLANK($B$6),0,IF(($F$26+7>=$B$6)*($F$26+7<=$C$6),$C$6+8-WEEKDAY($C$6,2)-($F$26+7),0))
E28: SW 13 | F28: =$F$27+7+IF(ISBLANK($B$3),0,IF(($F$27+7>=$B$3)*($F$27+7<=$C$3),$C$3+8-WEEKDAY($C$3,2)-($F$27+7),0))+IF(ISBLANK($B$4),0,IF(($F$27+7>=$B$4)*($F$27+7<=$C$4),$C$4+8-WEEKDAY($C$4,2)-($F$27+7),0))+IF(ISBLANK($B$5),0,IF(($F$27+7>=$B$5)*($F$27+7<=$C$5),$C$5+8-WEEKDAY($C$5,2)-($F$27+7),0))+IF(ISBLANK($B$6),0,IF(($F$27+7>=$B$6)*($F$27+7<=$C$6),$C$6+8-WEEKDAY($C$6,2)-($F$27+7),0))
E29: SW 14 | F29: =$F$28+7+IF(ISBLANK($B$3),0,IF(($F$28+7>=$B$3)*($F$28+7<=$C$3),$C$3+8-WEEKDAY($C$3,2)-($F$28+7),0))+IF(ISBLANK($B$4),0,IF(($F$28+7>=$B$4)*($F$28+7<=$C$4),$C$4+8-WEEKDAY($C$4,2)-($F$28+7),0))+IF(ISBLANK($B$5),0,IF(($F$28+7>=$B$5)*($F$28+7<=$C$5),$C$5+8-WEEKDAY($C$5,2)-($F$28+7),0))+IF(ISBLANK($B$6),0,IF(($F$28+7>=$B$6)*($F$28+7<=$C$6),$C$6+8-WEEKDAY($C$6,2)-($F$28+7),0))
E30: SW 15 | F30: =$F$29+7+IF(ISBLANK($B$3),0,IF(($F$29+7>=$B$3)*($F$29+7<=$C$3),$C$3+8-WEEKDAY($C$3,2)-($F$29+7),0))+IF(ISBLANK($B$4),0,IF(($F$29+7>=$B$4)*($F$29+7<=$C$4),$C$4+8-WEEKDAY($C$4,2)-($F$29+7),0))+IF(ISBLANK($B$5),0,IF(($F$29+7>=$B$5)*($F$29+7<=$C$5),$C$5+8-WEEKDAY($C$5,2)-($F$29+7),0))+IF(ISBLANK($B$6),0,IF(($F$29+7>=$B$6)*($F$29+7<=$C$6),$C$6+8-WEEKDAY($C$6,2)-($F$29+7),0))
E31: SW 16 | F31: =$F$30+7+IF(ISBLANK($B$3),0,IF(($F$30+7>=$B$3)*($F$30+7<=$C$3),$C$3+8-WEEKDAY($C$3,2)-($F$30+7),0))+IF(ISBLANK($B$4),0,IF(($F$30+7>=$B$4)*($F$30+7<=$C$4),$C$4+8-WEEKDAY($C$4,2)-($F$30+7),0))+IF(ISBLANK($B$5),0,IF(($F$30+7>=$B$5)*($F$30+7<=$C$5),$C$5+8-WEEKDAY($C$5,2)-($F$30+7),0))+IF(ISBLANK($B$6),0,IF(($F$30+7>=$B$6)*($F$30+7<=$C$6),$C$6+8-WEEKDAY($C$6,2)-($F$30+7),0))
E32: SW 17 | F32: =$F$31+7+IF(ISBLANK($B$3),0,IF(($F$31+7>=$B$3)*($F$31+7<=$C$3),$C$3+8-WEEKDAY($C$3,2)-($F$31+7),0))+IF(ISBLANK($B$4),0,IF(($F$31+7>=$B$4)*($F$31+7<=$C$4),$C$4+8-WEEKDAY($C$4,2)-($F$31+7),0))+IF(ISBLANK($B$5),0,IF(($F$31+7>=$B$5)*($F$31+7<=$C$5),$C$5+8-WEEKDAY($C$5,2)-($F$31+7),0))+IF(ISBLANK($B$6),0,IF(($F$31+7>=$B$6)*($F$31+7<=$C$6),$C$6+8-WEEKDAY($C$6,2)-($F$31+7),0))
E33: SW 18 | F33: =$F$32+7+IF(ISBLANK($B$3),0,IF(($F$32+7>=$B$3)*($F$32+7<=$C$3),$C$3+8-WEEKDAY($C$3,2)-($F$32+7),0))+IF(ISBLANK($B$4),0,IF(($F$32+7>=$B$4)*($F$32+7<=$C$4),$C$4+8-WEEKDAY($C$4,2)-($F$32+7),0))+IF(ISBLANK($B$5),0,IF(($F$32+7>=$B$5)*($F$32+7<=$C$5),$C$5+8-WEEKDAY($C$5,2)-($F$32+7),0))+IF(ISBLANK($B$6),0,IF(($F$32+7>=$B$6)*($F$32+7<=$C$6),$C$6+8-WEEKDAY($C$6,2)-($F$32+7),0))
E34: SW 19 | F34: =$F$33+7+IF(ISBLANK($B$3),0,IF(($F$33+7>=$B$3)*($F$33+7<=$C$3),$C$3+8-WEEKDAY($C$3,2)-($F$33+7),0))+IF(ISBLANK($B$4),0,IF(($F$33+7>=$B$4)*($F$33+7<=$C$4),$C$4+8-WEEKDAY($C$4,2)-($F$33+7),0))+IF(ISBLANK($B$5),0,IF(($F$33+7>=$B$5)*($F$33+7<=$C$5),$C$5+8-WEEKDAY($C$5,2)-($F$33+7),0))+IF(ISBLANK($B$6),0,IF(($F$33+7>=$B$6)*($F$33+7<=$C$6),$C$6+8-WEEKDAY($C$6,2)-($F$33+7),0))
E35: SW 20 | F35: =$F$34+7+IF(ISBLANK($B$3),0,IF(($F$34+7>=$B$3)*($F$34+7<=$C$3),$C$3+8-WEEKDAY($C$3,2)-($F$34+7),0))+IF(ISBLANK($B$4),0,IF(($F$34+7>=$B$4)*($F$34+7<=$C$4),$C$4+8-WEEKDAY($C$4,2)-($F$34+7),0))+IF(ISBLANK($B$5),0,IF(($F$34+7>=$B$5)*($F$34+7<=$C$5),$C$5+8-WEEKDAY($C$5,2)-($F$34+7),0))+IF(ISBLANK($B$6),0,IF(($F$34+7>=$B$6)*($F$34+7<=$C$6),$C$6+8-WEEKDAY($C$6,2)-($F$34+7),0))
E36: SW 21 | F36: =$F$35+7+IF(ISBLANK($B$3),0,IF(($F$35+7>=$B$3)*($F$35+7<=$C$3),$C$3+8-WEEKDAY($C$3,2)-($F$35+7),0))+IF(ISBLANK($B$4),0,IF(($F$35+7>=$B$4)*($F$35+7<=$C$4),$C$4+8-WEEKDAY($C$4,2)-($F$35+7),0))+IF(ISBLANK($B$5),0,IF(($F$35+7>=$B$5)*($F$35+7<=$C$5),$C$5+8-WEEKDAY($C$5,2)-($F$35+7),0))+IF(ISBLANK($B$6),0,IF(($F$35+7>=$B$6)*($F$35+7<=$C$6),$C$6+8-WEEKDAY($C$6,2)-($F$35+7),0))
E37: SW 22 | F37: =$F$36+7+IF(ISBLANK($B$3),0,IF(($F$36+7>=$B$3)*($F$36+7<=$C$3),$C$3+8-WEEKDAY($C$3,2)-($F$36+7),0))+IF(ISBLANK($B$4),0,IF(($F$36+7>=$B$4)*($F$36+7<=$C$4),$C$4+8-WEEKDAY($C$4,2)-($F$36+7),0))+IF(ISBLANK($B$5),0,IF(($F$36+7>=$B$5)*($F$36+7<=$C$5),$C$5+8-WEEKDAY($C$5,2)-($F$36+7),0))+IF(ISBLANK($B$6),0,IF(($F$36+7>=$B$6)*($F$36+7<=$C$6),$C$6+8-WEEKDAY($C$6,2)-($F$36+7),0))
E38: SW 23 | F38: =$F$37+7+IF(ISBLANK($B$3),0,IF(($F$37+7>=$B$3)*($F$37+7<=$C$3),$C$3+8-WEEKDAY($C$3,2)-($F$37+7),0))+IF(ISBLANK($B$4),0,IF(($F$37+7>=$B$4)*($F$37+7<=$C$4),$C$4+8-WEEKDAY($C$4,2)-($F$37+7),0))+IF(ISBLANK($B$5),0,IF(($F$37+7>=$B$5)*($F$37+7<=$C$5),$C$5+8-WEEKDAY($C$5,2)-($F$37+7),0))+IF(ISBLANK($B$6),0,IF(($F$37+7>=$B$6)*($F$37+7<=$C$6),$C$6+8-WEEKDAY($C$6,2)-($F$37+7),0))
E39: SW 24 | F39: =$F$38+7+IF(ISBLANK($B$3),0,IF(($F$38+7>=$B$3)*($F$38+7<=$C$3),$C$3+8-WEEKDAY($C$3,2)-($F$38+7),0))+IF(ISBLANK($B$4),0,IF(($F$38+7>=$B$4)*($F$38+7<=$C$4),$C$4+8-WEEKDAY($C$4,2)-($F$38+7),0))+IF(ISBLANK($B$5),0,IF(($F$38+7>=$B$5)*($F$38+7<=$C$5),$C$5+8-WEEKDAY($C$5,2)-($F$38+7),0))+IF(ISBLANK($B$6),0,IF(($F$38+7>=$B$6)*($F$38+7<=$C$6),$C$6+8-WEEKDAY($C$6,2)-($F$38+7),0))
E40: SW 25 | F40: =$F$39+7+IF(ISBLANK($B$3),0,IF(($F$39+7>=$B$3)*($F$39+7<=$C$3),$C$3+8-WEEKDAY($C$3,2)-($F$39+7),0))+IF(ISBLANK($B$4),0,IF(($F$39+7>=$B$4)*($F$39+7<=$C$4),$C$4+8-WEEKDAY($C$4,2)-($F$39+7),0))+IF(ISBLANK($B$5),0,IF(($F$39+7>=$B$5)*($F$39+7<=$C$5),$C$5+8-WEEKDAY($C$5,2)-($F$39+7),0))+IF(ISBLANK($B$6),0,IF(($F$39+7>=$B$6)*($F$39+7<=$C$6),$C$6+8-WEEKDAY($C$6,2)-($F$39+7),0))
E41: SW 26 | F41: =$F$40+7+IF(ISBLANK($B$3),0,IF(($F$40+7>=$B$3)*($F$40+7<=$C$3),$C$3+8-WEEKDAY($C$3,2)-($F$40+7),0))+IF(ISBLANK($B$4),0,IF(($F$40+7>=$B$4)*($F$40+7<=$C$4),$C$4+8-WEEKDAY($C$4,2)-($F$40+7),0))+IF(ISBLANK($B$5),0,IF(($F$40+7>=$B$5)*($F$40+7<=$C$5),$C$5+8-WEEKDAY($C$5,2)-($F$40+7),0))+IF(ISBLANK($B$6),0,IF(($F$40+7>=$B$6)*($F$40+7<=$C$6),$C$6+8-WEEKDAY($C$6,2)-($F$40+7),0))
E42: SW 27 | F42: =$F$41+7+IF(ISBLANK($B$3),0,IF(($F$41+7>=$B$3)*($F$41+7<=$C$3),$C$3+8-WEEKDAY($C$3,2)-($F$41+7),0))+IF(ISBLANK($B$4),0,IF(($F$41+7>=$B$4)*($F$41+7<=$C$4),$C$4+8-WEEKDAY($C$4,2)-($F$41+7),0))+IF(ISBLANK($B$5),0,IF(($F$41+7>=$B$5)*($F$41+7<=$C$5),$C$5+8-WEEKDAY($C$5,2)-($F$41+7),0))+IF(ISBLANK($B$6),0,IF(($F$41+7>=$B$6)*($F$41+7<=$C$6),$C$6+8-WEEKDAY($C$6,2)-($F$41+7),0))
...

Sheet Kategorien
A1: Kategorien-Referenz
A2: Kategorie | B2: Farbe | C2: Automatisch erkannte Stichwörter
A3: Jahrgang 5/6 | B3: #FADBD8 | C3: Jg 5, Jg 6, Klasse 5, Klasse 6, DST, Sprachstandstest, Neue 5er, Einschulung
A4: Jahrgang 7/8 | B4: #D5F5E3 | C4: Jg 7, Jg 8, Potenzialanalyse, Sexualerziehung 8, KAoA, WPM, WP-Wahl
A5: Jahrgang 9/10 | B5: #FDE8D3 | C5: Jg 9, Jg 10, Betriebspraktikum, BP, ZP 10, mAP 10, ZAA, Abschlussfahrt 10
A6: Oberstufe | B6: #D4E6F1 | C6: EF, Q1, Q2, Abi, Abitur, Klausur, ZKL 11, Kurswahl, Studienfahrt, Laufbahnkonferenz
A7: Inklusion | B7: #D1F2EB | C7: IFÖ, AL, AL-SuS, Förderplan, Förderpläne, AOSF, I-Helfer, Förderlehrer, Fö-LuL, Beratungsteam
A8: Feiertage/Ferien | B8: #FDEBD0 | C8: Ferien, Feiertag, Schulfrei, Weihnachten, Ostern, Pfingsten, Chanukka, Ramadan, Newroz
A9: Konferenzen/DB | B9: #E8DAEF | C9: LK, FaKo, PK, ZK, SK, KK, DB, TBS, Dienstbesprechung, Schulkonferenz, Projektgruppen
